[2024-07-30T18:23:31.319+0000] {local_task_job_runner.py:120} INFO - ::group::Pre task execution logs
[2024-07-30T18:23:31.353+0000] {taskinstance.py:2076} INFO - Dependencies all met for dep_context=non-requeueable deps ti=<TaskInstance: Pipeline.data_cleansing scheduled__2024-07-30T18:20:00+00:00 [queued]>
[2024-07-30T18:23:31.367+0000] {taskinstance.py:2076} INFO - Dependencies all met for dep_context=requeueable deps ti=<TaskInstance: Pipeline.data_cleansing scheduled__2024-07-30T18:20:00+00:00 [queued]>
[2024-07-30T18:23:31.369+0000] {taskinstance.py:2306} INFO - Starting attempt 2 of 2
[2024-07-30T18:23:31.386+0000] {taskinstance.py:2330} INFO - Executing <Task(PythonOperator): data_cleansing> on 2024-07-30 18:20:00+00:00
[2024-07-30T18:23:31.394+0000] {standard_task_runner.py:64} INFO - Started process 375 to run task
[2024-07-30T18:23:31.397+0000] {standard_task_runner.py:90} INFO - Running: ['***', 'tasks', 'run', 'Pipeline', 'data_cleansing', 'scheduled__2024-07-30T18:20:00+00:00', '--job-id', '477', '--raw', '--subdir', 'DAGS_FOLDER/pipeline.py', '--cfg-path', '/tmp/tmpv0jtv5h0']
[2024-07-30T18:23:31.401+0000] {standard_task_runner.py:91} INFO - Job 477: Subtask data_cleansing
[2024-07-30T18:23:31.461+0000] {task_command.py:426} INFO - Running <TaskInstance: Pipeline.data_cleansing scheduled__2024-07-30T18:20:00+00:00 [running]> on host f17ca52b44b4
[2024-07-30T18:23:31.587+0000] {taskinstance.py:2648} INFO - Exporting env vars: AIRFLOW_CTX_DAG_OWNER='***' AIRFLOW_CTX_DAG_ID='Pipeline' AIRFLOW_CTX_TASK_ID='data_cleansing' AIRFLOW_CTX_EXECUTION_DATE='2024-07-30T18:20:00+00:00' AIRFLOW_CTX_TRY_NUMBER='2' AIRFLOW_CTX_DAG_RUN_ID='scheduled__2024-07-30T18:20:00+00:00'
[2024-07-30T18:23:31.589+0000] {taskinstance.py:430} INFO - ::endgroup::
[2024-07-30T18:23:31.599+0000] {taskinstance.py:441} INFO - ::group::Post task execution logs
[2024-07-30T18:23:31.600+0000] {taskinstance.py:2905} ERROR - Task failed with exception
Traceback (most recent call last):
  File "/home/airflow/.local/lib/python3.8/site-packages/airflow/models/taskinstance.py", line 465, in _execute_task
    result = _execute_callable(context=context, **execute_callable_kwargs)
  File "/home/airflow/.local/lib/python3.8/site-packages/airflow/models/taskinstance.py", line 432, in _execute_callable
    return execute_callable(context=context, **execute_callable_kwargs)
  File "/home/airflow/.local/lib/python3.8/site-packages/airflow/models/baseoperator.py", line 401, in wrapper
    return func(self, *args, **kwargs)
  File "/home/airflow/.local/lib/python3.8/site-packages/airflow/operators/python.py", line 235, in execute
    return_value = self.execute_callable()
  File "/home/airflow/.local/lib/python3.8/site-packages/airflow/operators/python.py", line 252, in execute_callable
    return self.python_callable(*self.op_args, **self.op_kwargs)
TypeError: data_cleansing() missing 1 required positional argument: 'data_df'
[2024-07-30T18:23:31.607+0000] {taskinstance.py:1206} INFO - Marking task as FAILED. dag_id=Pipeline, task_id=data_cleansing, run_id=scheduled__2024-07-30T18:20:00+00:00, execution_date=20240730T182000, start_date=20240730T182331, end_date=20240730T182331
[2024-07-30T18:23:31.630+0000] {standard_task_runner.py:110} ERROR - Failed to execute job 477 for task data_cleansing (data_cleansing() missing 1 required positional argument: 'data_df'; 375)
[2024-07-30T18:23:31.651+0000] {local_task_job_runner.py:243} INFO - Task exited with return code 1
[2024-07-30T18:23:31.675+0000] {taskinstance.py:3503} INFO - 0 downstream tasks scheduled from follow-on schedule check
[2024-07-30T18:23:31.679+0000] {local_task_job_runner.py:222} INFO - ::endgroup::
