[2024-07-30T18:22:27.021+0000] {local_task_job_runner.py:120} INFO - ::group::Pre task execution logs
[2024-07-30T18:22:27.046+0000] {taskinstance.py:2076} INFO - Dependencies all met for dep_context=non-requeueable deps ti=<TaskInstance: Pipeline.data_cleansing scheduled__2024-07-30T18:20:00+00:00 [queued]>
[2024-07-30T18:22:27.059+0000] {taskinstance.py:2076} INFO - Dependencies all met for dep_context=requeueable deps ti=<TaskInstance: Pipeline.data_cleansing scheduled__2024-07-30T18:20:00+00:00 [queued]>
[2024-07-30T18:22:27.060+0000] {taskinstance.py:2306} INFO - Starting attempt 1 of 2
[2024-07-30T18:22:27.073+0000] {taskinstance.py:2330} INFO - Executing <Task(PythonOperator): data_cleansing> on 2024-07-30 18:20:00+00:00
[2024-07-30T18:22:27.085+0000] {standard_task_runner.py:64} INFO - Started process 326 to run task
[2024-07-30T18:22:27.088+0000] {standard_task_runner.py:90} INFO - Running: ['***', 'tasks', 'run', 'Pipeline', 'data_cleansing', 'scheduled__2024-07-30T18:20:00+00:00', '--job-id', '476', '--raw', '--subdir', 'DAGS_FOLDER/pipeline.py', '--cfg-path', '/tmp/tmpyzo9336z']
[2024-07-30T18:22:27.103+0000] {standard_task_runner.py:91} INFO - Job 476: Subtask data_cleansing
[2024-07-30T18:22:27.171+0000] {task_command.py:426} INFO - Running <TaskInstance: Pipeline.data_cleansing scheduled__2024-07-30T18:20:00+00:00 [running]> on host f17ca52b44b4
[2024-07-30T18:22:27.278+0000] {taskinstance.py:2648} INFO - Exporting env vars: AIRFLOW_CTX_DAG_OWNER='***' AIRFLOW_CTX_DAG_ID='Pipeline' AIRFLOW_CTX_TASK_ID='data_cleansing' AIRFLOW_CTX_EXECUTION_DATE='2024-07-30T18:20:00+00:00' AIRFLOW_CTX_TRY_NUMBER='1' AIRFLOW_CTX_DAG_RUN_ID='scheduled__2024-07-30T18:20:00+00:00'
[2024-07-30T18:22:27.279+0000] {taskinstance.py:430} INFO - ::endgroup::
[2024-07-30T18:22:27.290+0000] {taskinstance.py:441} INFO - ::group::Post task execution logs
[2024-07-30T18:22:27.290+0000] {taskinstance.py:2905} ERROR - Task failed with exception
Traceback (most recent call last):
  File "/home/airflow/.local/lib/python3.8/site-packages/airflow/models/taskinstance.py", line 465, in _execute_task
    result = _execute_callable(context=context, **execute_callable_kwargs)
  File "/home/airflow/.local/lib/python3.8/site-packages/airflow/models/taskinstance.py", line 432, in _execute_callable
    return execute_callable(context=context, **execute_callable_kwargs)
  File "/home/airflow/.local/lib/python3.8/site-packages/airflow/models/baseoperator.py", line 401, in wrapper
    return func(self, *args, **kwargs)
  File "/home/airflow/.local/lib/python3.8/site-packages/airflow/operators/python.py", line 235, in execute
    return_value = self.execute_callable()
  File "/home/airflow/.local/lib/python3.8/site-packages/airflow/operators/python.py", line 252, in execute_callable
    return self.python_callable(*self.op_args, **self.op_kwargs)
TypeError: data_cleansing() missing 1 required positional argument: 'data_df'
[2024-07-30T18:22:27.298+0000] {taskinstance.py:1206} INFO - Marking task as UP_FOR_RETRY. dag_id=Pipeline, task_id=data_cleansing, run_id=scheduled__2024-07-30T18:20:00+00:00, execution_date=20240730T182000, start_date=20240730T182227, end_date=20240730T182227
[2024-07-30T18:22:27.310+0000] {standard_task_runner.py:110} ERROR - Failed to execute job 476 for task data_cleansing (data_cleansing() missing 1 required positional argument: 'data_df'; 326)
[2024-07-30T18:22:27.318+0000] {local_task_job_runner.py:243} INFO - Task exited with return code 1
[2024-07-30T18:22:27.340+0000] {taskinstance.py:3503} INFO - 0 downstream tasks scheduled from follow-on schedule check
[2024-07-30T18:22:27.346+0000] {local_task_job_runner.py:222} INFO - ::endgroup::
