[2024-07-30T23:49:57.045+0000] {local_task_job_runner.py:120} INFO - ::group::Pre task execution logs
[2024-07-30T23:49:57.066+0000] {taskinstance.py:2076} INFO - Dependencies all met for dep_context=non-requeueable deps ti=<TaskInstance: Pipeline.data_cleansing scheduled__2024-07-30T23:38:00+00:00 [queued]>
[2024-07-30T23:49:57.077+0000] {taskinstance.py:2076} INFO - Dependencies all met for dep_context=requeueable deps ti=<TaskInstance: Pipeline.data_cleansing scheduled__2024-07-30T23:38:00+00:00 [queued]>
[2024-07-30T23:49:57.078+0000] {taskinstance.py:2306} INFO - Starting attempt 2 of 2
[2024-07-30T23:49:57.090+0000] {taskinstance.py:2330} INFO - Executing <Task(PythonOperator): data_cleansing> on 2024-07-30 23:38:00+00:00
[2024-07-30T23:49:57.099+0000] {standard_task_runner.py:64} INFO - Started process 3128 to run task
[2024-07-30T23:49:57.103+0000] {standard_task_runner.py:90} INFO - Running: ['***', 'tasks', 'run', 'Pipeline', 'data_cleansing', 'scheduled__2024-07-30T23:38:00+00:00', '--job-id', '520', '--raw', '--subdir', 'DAGS_FOLDER/pipeline.py', '--cfg-path', '/tmp/tmpii_d5scm']
[2024-07-30T23:49:57.106+0000] {standard_task_runner.py:91} INFO - Job 520: Subtask data_cleansing
[2024-07-30T23:49:57.158+0000] {task_command.py:426} INFO - Running <TaskInstance: Pipeline.data_cleansing scheduled__2024-07-30T23:38:00+00:00 [running]> on host f17ca52b44b4
[2024-07-30T23:49:57.239+0000] {taskinstance.py:2648} INFO - Exporting env vars: AIRFLOW_CTX_DAG_OWNER='***' AIRFLOW_CTX_DAG_ID='Pipeline' AIRFLOW_CTX_TASK_ID='data_cleansing' AIRFLOW_CTX_EXECUTION_DATE='2024-07-30T23:38:00+00:00' AIRFLOW_CTX_TRY_NUMBER='2' AIRFLOW_CTX_DAG_RUN_ID='scheduled__2024-07-30T23:38:00+00:00'
[2024-07-30T23:49:57.241+0000] {taskinstance.py:430} INFO - ::endgroup::
[2024-07-30T23:49:57.282+0000] {taskinstance.py:441} INFO - ::group::Post task execution logs
[2024-07-30T23:49:57.283+0000] {taskinstance.py:2905} ERROR - Task failed with exception
Traceback (most recent call last):
  File "/home/airflow/.local/lib/python3.8/site-packages/airflow/models/taskinstance.py", line 465, in _execute_task
    result = _execute_callable(context=context, **execute_callable_kwargs)
  File "/home/airflow/.local/lib/python3.8/site-packages/airflow/models/taskinstance.py", line 432, in _execute_callable
    return execute_callable(context=context, **execute_callable_kwargs)
  File "/home/airflow/.local/lib/python3.8/site-packages/airflow/models/baseoperator.py", line 401, in wrapper
    return func(self, *args, **kwargs)
  File "/home/airflow/.local/lib/python3.8/site-packages/airflow/operators/python.py", line 235, in execute
    return_value = self.execute_callable()
  File "/home/airflow/.local/lib/python3.8/site-packages/airflow/operators/python.py", line 252, in execute_callable
    return self.python_callable(*self.op_args, **self.op_kwargs)
  File "/opt/airflow/dags/funtions.py", line 117, in data_cleansing
    data_df=pd.read_parquet(temp_file)
  File "/home/airflow/.local/lib/python3.8/site-packages/pandas/io/parquet.py", line 509, in read_parquet
    return impl.read(
  File "/home/airflow/.local/lib/python3.8/site-packages/pandas/io/parquet.py", line 227, in read
    pa_table = self.api.parquet.read_table(
  File "/home/airflow/.local/lib/python3.8/site-packages/pyarrow/parquet/core.py", line 1762, in read_table
    dataset = ParquetDataset(
  File "/home/airflow/.local/lib/python3.8/site-packages/pyarrow/parquet/core.py", line 1340, in __init__
    self._dataset = ds.dataset(path_or_paths, filesystem=filesystem,
  File "/home/airflow/.local/lib/python3.8/site-packages/pyarrow/dataset.py", line 814, in dataset
    raise TypeError(
TypeError: Expected a path-like, list of path-likes or a list of Datasets instead of the given type: NoneType
[2024-07-30T23:49:57.299+0000] {taskinstance.py:1206} INFO - Marking task as FAILED. dag_id=Pipeline, task_id=data_cleansing, run_id=scheduled__2024-07-30T23:38:00+00:00, execution_date=20240730T233800, start_date=20240730T234957, end_date=20240730T234957
[2024-07-30T23:49:57.317+0000] {standard_task_runner.py:110} ERROR - Failed to execute job 520 for task data_cleansing (Expected a path-like, list of path-likes or a list of Datasets instead of the given type: NoneType; 3128)
[2024-07-30T23:49:57.357+0000] {local_task_job_runner.py:243} INFO - Task exited with return code 1
[2024-07-30T23:49:57.373+0000] {taskinstance.py:3503} INFO - 0 downstream tasks scheduled from follow-on schedule check
[2024-07-30T23:49:57.375+0000] {local_task_job_runner.py:222} INFO - ::endgroup::
