[2024-07-30T20:35:24.024+0000] {local_task_job_runner.py:120} INFO - ::group::Pre task execution logs
[2024-07-30T20:35:24.045+0000] {taskinstance.py:2076} INFO - Dependencies all met for dep_context=non-requeueable deps ti=<TaskInstance: Pipeline.transforms_data scheduled__2024-07-30T20:29:00+00:00 [queued]>
[2024-07-30T20:35:24.053+0000] {taskinstance.py:2076} INFO - Dependencies all met for dep_context=requeueable deps ti=<TaskInstance: Pipeline.transforms_data scheduled__2024-07-30T20:29:00+00:00 [queued]>
[2024-07-30T20:35:24.057+0000] {taskinstance.py:2306} INFO - Starting attempt 2 of 2
[2024-07-30T20:35:24.070+0000] {taskinstance.py:2330} INFO - Executing <Task(PythonOperator): transforms_data> on 2024-07-30 20:29:00+00:00
[2024-07-30T20:35:24.083+0000] {standard_task_runner.py:64} INFO - Started process 6382 to run task
[2024-07-30T20:35:24.086+0000] {standard_task_runner.py:90} INFO - Running: ['***', 'tasks', 'run', 'Pipeline', 'transforms_data', 'scheduled__2024-07-30T20:29:00+00:00', '--job-id', '496', '--raw', '--subdir', 'DAGS_FOLDER/pipeline.py', '--cfg-path', '/tmp/tmpssnu_yvy']
[2024-07-30T20:35:24.092+0000] {standard_task_runner.py:91} INFO - Job 496: Subtask transforms_data
[2024-07-30T20:35:24.138+0000] {task_command.py:426} INFO - Running <TaskInstance: Pipeline.transforms_data scheduled__2024-07-30T20:29:00+00:00 [running]> on host f17ca52b44b4
[2024-07-30T20:35:24.303+0000] {taskinstance.py:2648} INFO - Exporting env vars: AIRFLOW_CTX_DAG_OWNER='***' AIRFLOW_CTX_DAG_ID='Pipeline' AIRFLOW_CTX_TASK_ID='transforms_data' AIRFLOW_CTX_EXECUTION_DATE='2024-07-30T20:29:00+00:00' AIRFLOW_CTX_TRY_NUMBER='2' AIRFLOW_CTX_DAG_RUN_ID='scheduled__2024-07-30T20:29:00+00:00'
[2024-07-30T20:35:24.306+0000] {taskinstance.py:430} INFO - ::endgroup::
[2024-07-30T20:35:24.359+0000] {taskinstance.py:441} INFO - ::group::Post task execution logs
[2024-07-30T20:35:24.364+0000] {taskinstance.py:2905} ERROR - Task failed with exception
Traceback (most recent call last):
  File "/home/airflow/.local/lib/python3.8/site-packages/airflow/models/taskinstance.py", line 465, in _execute_task
    result = _execute_callable(context=context, **execute_callable_kwargs)
  File "/home/airflow/.local/lib/python3.8/site-packages/airflow/models/taskinstance.py", line 432, in _execute_callable
    return execute_callable(context=context, **execute_callable_kwargs)
  File "/home/airflow/.local/lib/python3.8/site-packages/airflow/models/baseoperator.py", line 401, in wrapper
    return func(self, *args, **kwargs)
  File "/home/airflow/.local/lib/python3.8/site-packages/airflow/operators/python.py", line 235, in execute
    return_value = self.execute_callable()
  File "/home/airflow/.local/lib/python3.8/site-packages/airflow/operators/python.py", line 252, in execute_callable
    return self.python_callable(*self.op_args, **self.op_kwargs)
  File "/opt/airflow/dags/funtions.py", line 46, in transform_data
    data_df=pd.read_parquet(temp_file)
  File "/home/airflow/.local/lib/python3.8/site-packages/pandas/io/parquet.py", line 509, in read_parquet
    return impl.read(
  File "/home/airflow/.local/lib/python3.8/site-packages/pandas/io/parquet.py", line 227, in read
    pa_table = self.api.parquet.read_table(
  File "/home/airflow/.local/lib/python3.8/site-packages/pyarrow/parquet/core.py", line 1762, in read_table
    dataset = ParquetDataset(
  File "/home/airflow/.local/lib/python3.8/site-packages/pyarrow/parquet/core.py", line 1340, in __init__
    self._dataset = ds.dataset(path_or_paths, filesystem=filesystem,
  File "/home/airflow/.local/lib/python3.8/site-packages/pyarrow/dataset.py", line 814, in dataset
    raise TypeError(
TypeError: Expected a path-like, list of path-likes or a list of Datasets instead of the given type: NoneType
[2024-07-30T20:35:24.413+0000] {taskinstance.py:1206} INFO - Marking task as FAILED. dag_id=Pipeline, task_id=transforms_data, run_id=scheduled__2024-07-30T20:29:00+00:00, execution_date=20240730T202900, start_date=20240730T203524, end_date=20240730T203524
[2024-07-30T20:35:24.426+0000] {standard_task_runner.py:110} ERROR - Failed to execute job 496 for task transforms_data (Expected a path-like, list of path-likes or a list of Datasets instead of the given type: NoneType; 6382)
[2024-07-30T20:35:24.461+0000] {local_task_job_runner.py:243} INFO - Task exited with return code 1
[2024-07-30T20:35:24.494+0000] {taskinstance.py:3503} INFO - 0 downstream tasks scheduled from follow-on schedule check
[2024-07-30T20:35:24.498+0000] {local_task_job_runner.py:222} INFO - ::endgroup::
