[2024-07-31T03:10:14.449+0000] {local_task_job_runner.py:120} INFO - ::group::Pre task execution logs
[2024-07-31T03:10:14.471+0000] {taskinstance.py:2076} INFO - Dependencies all met for dep_context=non-requeueable deps ti=<TaskInstance: Pipeline.data_cleansing scheduled__2024-07-31T03:07:00+00:00 [queued]>
[2024-07-31T03:10:14.483+0000] {taskinstance.py:2076} INFO - Dependencies all met for dep_context=requeueable deps ti=<TaskInstance: Pipeline.data_cleansing scheduled__2024-07-31T03:07:00+00:00 [queued]>
[2024-07-31T03:10:14.488+0000] {taskinstance.py:2306} INFO - Starting attempt 2 of 2
[2024-07-31T03:10:14.503+0000] {taskinstance.py:2330} INFO - Executing <Task(PythonOperator): data_cleansing> on 2024-07-31 03:07:00+00:00
[2024-07-31T03:10:14.515+0000] {standard_task_runner.py:64} INFO - Started process 14459 to run task
[2024-07-31T03:10:14.518+0000] {standard_task_runner.py:90} INFO - Running: ['***', 'tasks', 'run', 'Pipeline', 'data_cleansing', 'scheduled__2024-07-31T03:07:00+00:00', '--job-id', '639', '--raw', '--subdir', 'DAGS_FOLDER/pipeline.py', '--cfg-path', '/tmp/tmpy2_5fz0l']
[2024-07-31T03:10:14.529+0000] {standard_task_runner.py:91} INFO - Job 639: Subtask data_cleansing
[2024-07-31T03:10:14.660+0000] {task_command.py:426} INFO - Running <TaskInstance: Pipeline.data_cleansing scheduled__2024-07-31T03:07:00+00:00 [running]> on host f17ca52b44b4
[2024-07-31T03:10:14.841+0000] {taskinstance.py:2648} INFO - Exporting env vars: AIRFLOW_CTX_DAG_OWNER='***' AIRFLOW_CTX_DAG_ID='Pipeline' AIRFLOW_CTX_TASK_ID='data_cleansing' AIRFLOW_CTX_EXECUTION_DATE='2024-07-31T03:07:00+00:00' AIRFLOW_CTX_TRY_NUMBER='2' AIRFLOW_CTX_DAG_RUN_ID='scheduled__2024-07-31T03:07:00+00:00'
[2024-07-31T03:10:14.849+0000] {taskinstance.py:430} INFO - ::endgroup::
[2024-07-31T03:10:15.284+0000] {taskinstance.py:441} INFO - ::group::Post task execution logs
[2024-07-31T03:10:15.285+0000] {taskinstance.py:2905} ERROR - Task failed with exception
Traceback (most recent call last):
  File "/home/airflow/.local/lib/python3.8/site-packages/airflow/models/taskinstance.py", line 465, in _execute_task
    result = _execute_callable(context=context, **execute_callable_kwargs)
  File "/home/airflow/.local/lib/python3.8/site-packages/airflow/models/taskinstance.py", line 432, in _execute_callable
    return execute_callable(context=context, **execute_callable_kwargs)
  File "/home/airflow/.local/lib/python3.8/site-packages/airflow/models/baseoperator.py", line 401, in wrapper
    return func(self, *args, **kwargs)
  File "/home/airflow/.local/lib/python3.8/site-packages/airflow/operators/python.py", line 235, in execute
    return_value = self.execute_callable()
  File "/home/airflow/.local/lib/python3.8/site-packages/airflow/operators/python.py", line 252, in execute_callable
    return self.python_callable(*self.op_args, **self.op_kwargs)
  File "/opt/airflow/dags/funtions.py", line 130, in data_cleansing
    data_df = data_df.drop(columns=['orden'])
  File "/home/airflow/.local/lib/python3.8/site-packages/pandas/core/frame.py", line 5258, in drop
    return super().drop(
  File "/home/airflow/.local/lib/python3.8/site-packages/pandas/core/generic.py", line 4549, in drop
    obj = obj._drop_axis(labels, axis, level=level, errors=errors)
  File "/home/airflow/.local/lib/python3.8/site-packages/pandas/core/generic.py", line 4591, in _drop_axis
    new_axis = axis.drop(labels, errors=errors)
  File "/home/airflow/.local/lib/python3.8/site-packages/pandas/core/indexes/base.py", line 6699, in drop
    raise KeyError(f"{list(labels[mask])} not found in axis")
KeyError: "['orden'] not found in axis"
[2024-07-31T03:10:15.407+0000] {taskinstance.py:1206} INFO - Marking task as FAILED. dag_id=Pipeline, task_id=data_cleansing, run_id=scheduled__2024-07-31T03:07:00+00:00, execution_date=20240731T030700, start_date=20240731T031014, end_date=20240731T031015
[2024-07-31T03:10:15.430+0000] {standard_task_runner.py:110} ERROR - Failed to execute job 639 for task data_cleansing ("['orden'] not found in axis"; 14459)
[2024-07-31T03:10:15.472+0000] {local_task_job_runner.py:243} INFO - Task exited with return code 1
[2024-07-31T03:10:15.509+0000] {taskinstance.py:3503} INFO - 0 downstream tasks scheduled from follow-on schedule check
[2024-07-31T03:10:15.525+0000] {local_task_job_runner.py:222} INFO - ::endgroup::
