[2024-07-31T03:09:10.813+0000] {local_task_job_runner.py:120} INFO - ::group::Pre task execution logs
[2024-07-31T03:09:10.837+0000] {taskinstance.py:2076} INFO - Dependencies all met for dep_context=non-requeueable deps ti=<TaskInstance: Pipeline.data_cleansing scheduled__2024-07-31T03:07:00+00:00 [queued]>
[2024-07-31T03:09:10.869+0000] {taskinstance.py:2076} INFO - Dependencies all met for dep_context=requeueable deps ti=<TaskInstance: Pipeline.data_cleansing scheduled__2024-07-31T03:07:00+00:00 [queued]>
[2024-07-31T03:09:10.870+0000] {taskinstance.py:2306} INFO - Starting attempt 1 of 2
[2024-07-31T03:09:10.887+0000] {taskinstance.py:2330} INFO - Executing <Task(PythonOperator): data_cleansing> on 2024-07-31 03:07:00+00:00
[2024-07-31T03:09:10.902+0000] {standard_task_runner.py:64} INFO - Started process 14381 to run task
[2024-07-31T03:09:10.905+0000] {standard_task_runner.py:90} INFO - Running: ['***', 'tasks', 'run', 'Pipeline', 'data_cleansing', 'scheduled__2024-07-31T03:07:00+00:00', '--job-id', '638', '--raw', '--subdir', 'DAGS_FOLDER/pipeline.py', '--cfg-path', '/tmp/tmpuaaz9m6k']
[2024-07-31T03:09:10.908+0000] {standard_task_runner.py:91} INFO - Job 638: Subtask data_cleansing
[2024-07-31T03:09:10.960+0000] {task_command.py:426} INFO - Running <TaskInstance: Pipeline.data_cleansing scheduled__2024-07-31T03:07:00+00:00 [running]> on host f17ca52b44b4
[2024-07-31T03:09:11.048+0000] {taskinstance.py:2648} INFO - Exporting env vars: AIRFLOW_CTX_DAG_OWNER='***' AIRFLOW_CTX_DAG_ID='Pipeline' AIRFLOW_CTX_TASK_ID='data_cleansing' AIRFLOW_CTX_EXECUTION_DATE='2024-07-31T03:07:00+00:00' AIRFLOW_CTX_TRY_NUMBER='1' AIRFLOW_CTX_DAG_RUN_ID='scheduled__2024-07-31T03:07:00+00:00'
[2024-07-31T03:09:11.050+0000] {taskinstance.py:430} INFO - ::endgroup::
[2024-07-31T03:09:11.381+0000] {logging_mixin.py:188} INFO - 

            fecha      hora  ... tipo_de_servicio franja horaria
0  02/01/2021  20:45:00  ...       PARTICULAR          Noche

[1 rows x 9 columns]
[2024-07-31T03:09:11.394+0000] {logging_mixin.py:188} INFO - Contenido verificado del Parquet file:
[2024-07-31T03:09:11.403+0000] {logging_mixin.py:188} INFO -         fecha      hora  ... tipo_de_servicio franja horaria
0  02/01/2021  20:45:00  ...       PARTICULAR          Noche
1  03/01/2021  11:50:00  ...          PUBLICO         Ma√±ana
2  04/01/2021  13:20:00  ...       PARTICULAR          Tarde
3  04/01/2021  15:30:00  ...          OFICIAL          Tarde
4  04/01/2021  19:00:00  ...       PARTICULAR          Noche

[5 rows x 9 columns]
[2024-07-31T03:09:11.404+0000] {taskinstance.py:441} INFO - ::group::Post task execution logs
[2024-07-31T03:09:11.404+0000] {taskinstance.py:2905} ERROR - Task failed with exception
Traceback (most recent call last):
  File "/home/airflow/.local/lib/python3.8/site-packages/airflow/models/taskinstance.py", line 465, in _execute_task
    result = _execute_callable(context=context, **execute_callable_kwargs)
  File "/home/airflow/.local/lib/python3.8/site-packages/airflow/models/taskinstance.py", line 432, in _execute_callable
    return execute_callable(context=context, **execute_callable_kwargs)
  File "/home/airflow/.local/lib/python3.8/site-packages/airflow/models/baseoperator.py", line 401, in wrapper
    return func(self, *args, **kwargs)
  File "/home/airflow/.local/lib/python3.8/site-packages/airflow/operators/python.py", line 235, in execute
    return_value = self.execute_callable()
  File "/home/airflow/.local/lib/python3.8/site-packages/airflow/operators/python.py", line 252, in execute_callable
    return self.python_callable(*self.op_args, **self.op_kwargs)
  File "/opt/airflow/dags/funtions.py", line 160, in data_cleansing
    context['ti'].xcom_pull(key='temp_file_path',value=temp_file)
  File "/home/airflow/.local/lib/python3.8/site-packages/airflow/utils/session.py", line 79, in wrapper
    return func(*args, session=session, **kwargs)
TypeError: xcom_pull() got an unexpected keyword argument 'value'
[2024-07-31T03:09:11.415+0000] {taskinstance.py:1206} INFO - Marking task as UP_FOR_RETRY. dag_id=Pipeline, task_id=data_cleansing, run_id=scheduled__2024-07-31T03:07:00+00:00, execution_date=20240731T030700, start_date=20240731T030910, end_date=20240731T030911
[2024-07-31T03:09:11.426+0000] {standard_task_runner.py:110} ERROR - Failed to execute job 638 for task data_cleansing (xcom_pull() got an unexpected keyword argument 'value'; 14381)
[2024-07-31T03:09:11.481+0000] {local_task_job_runner.py:243} INFO - Task exited with return code 1
[2024-07-31T03:09:11.526+0000] {taskinstance.py:3503} INFO - 0 downstream tasks scheduled from follow-on schedule check
[2024-07-31T03:09:11.539+0000] {local_task_job_runner.py:222} INFO - ::endgroup::
