[2024-07-30T20:45:20.819+0000] {local_task_job_runner.py:120} INFO - ::group::Pre task execution logs
[2024-07-30T20:45:20.842+0000] {taskinstance.py:2076} INFO - Dependencies all met for dep_context=non-requeueable deps ti=<TaskInstance: Pipeline.transforms_data scheduled__2024-07-30T20:43:00+00:00 [queued]>
[2024-07-30T20:45:20.850+0000] {taskinstance.py:2076} INFO - Dependencies all met for dep_context=requeueable deps ti=<TaskInstance: Pipeline.transforms_data scheduled__2024-07-30T20:43:00+00:00 [queued]>
[2024-07-30T20:45:20.852+0000] {taskinstance.py:2306} INFO - Starting attempt 2 of 2
[2024-07-30T20:45:20.867+0000] {taskinstance.py:2330} INFO - Executing <Task(PythonOperator): transforms_data> on 2024-07-30 20:43:00+00:00
[2024-07-30T20:45:20.877+0000] {standard_task_runner.py:64} INFO - Started process 7021 to run task
[2024-07-30T20:45:20.880+0000] {standard_task_runner.py:90} INFO - Running: ['***', 'tasks', 'run', 'Pipeline', 'transforms_data', 'scheduled__2024-07-30T20:43:00+00:00', '--job-id', '508', '--raw', '--subdir', 'DAGS_FOLDER/pipeline.py', '--cfg-path', '/tmp/tmpfor2b20v']
[2024-07-30T20:45:20.884+0000] {standard_task_runner.py:91} INFO - Job 508: Subtask transforms_data
[2024-07-30T20:45:20.974+0000] {task_command.py:426} INFO - Running <TaskInstance: Pipeline.transforms_data scheduled__2024-07-30T20:43:00+00:00 [running]> on host f17ca52b44b4
[2024-07-30T20:45:21.137+0000] {taskinstance.py:2648} INFO - Exporting env vars: AIRFLOW_CTX_DAG_OWNER='***' AIRFLOW_CTX_DAG_ID='Pipeline' AIRFLOW_CTX_TASK_ID='transforms_data' AIRFLOW_CTX_EXECUTION_DATE='2024-07-30T20:43:00+00:00' AIRFLOW_CTX_TRY_NUMBER='2' AIRFLOW_CTX_DAG_RUN_ID='scheduled__2024-07-30T20:43:00+00:00'
[2024-07-30T20:45:21.139+0000] {taskinstance.py:430} INFO - ::endgroup::
[2024-07-30T20:45:21.159+0000] {taskinstance.py:441} INFO - ::group::Post task execution logs
[2024-07-30T20:45:21.161+0000] {taskinstance.py:2905} ERROR - Task failed with exception
Traceback (most recent call last):
  File "/home/airflow/.local/lib/python3.8/site-packages/airflow/models/taskinstance.py", line 465, in _execute_task
    result = _execute_callable(context=context, **execute_callable_kwargs)
  File "/home/airflow/.local/lib/python3.8/site-packages/airflow/models/taskinstance.py", line 432, in _execute_callable
    return execute_callable(context=context, **execute_callable_kwargs)
  File "/home/airflow/.local/lib/python3.8/site-packages/airflow/models/baseoperator.py", line 401, in wrapper
    return func(self, *args, **kwargs)
  File "/home/airflow/.local/lib/python3.8/site-packages/airflow/operators/python.py", line 235, in execute
    return_value = self.execute_callable()
  File "/home/airflow/.local/lib/python3.8/site-packages/airflow/operators/python.py", line 252, in execute_callable
    return self.python_callable(*self.op_args, **self.op_kwargs)
  File "/opt/airflow/dags/funtions.py", line 47, in transform_data
    raise FileNotFoundError("The Parquet file does not exist. Please check the previous task.")
FileNotFoundError: The Parquet file does not exist. Please check the previous task.
[2024-07-30T20:45:21.180+0000] {taskinstance.py:1206} INFO - Marking task as FAILED. dag_id=Pipeline, task_id=transforms_data, run_id=scheduled__2024-07-30T20:43:00+00:00, execution_date=20240730T204300, start_date=20240730T204520, end_date=20240730T204521
[2024-07-30T20:45:21.191+0000] {standard_task_runner.py:110} ERROR - Failed to execute job 508 for task transforms_data (The Parquet file does not exist. Please check the previous task.; 7021)
[2024-07-30T20:45:21.215+0000] {local_task_job_runner.py:243} INFO - Task exited with return code 1
[2024-07-30T20:45:21.239+0000] {taskinstance.py:3503} INFO - 0 downstream tasks scheduled from follow-on schedule check
[2024-07-30T20:45:21.244+0000] {local_task_job_runner.py:222} INFO - ::endgroup::
