[2024-07-30T20:44:16.725+0000] {local_task_job_runner.py:120} INFO - ::group::Pre task execution logs
[2024-07-30T20:44:16.746+0000] {taskinstance.py:2076} INFO - Dependencies all met for dep_context=non-requeueable deps ti=<TaskInstance: Pipeline.transforms_data scheduled__2024-07-30T20:43:00+00:00 [queued]>
[2024-07-30T20:44:16.759+0000] {taskinstance.py:2076} INFO - Dependencies all met for dep_context=requeueable deps ti=<TaskInstance: Pipeline.transforms_data scheduled__2024-07-30T20:43:00+00:00 [queued]>
[2024-07-30T20:44:16.760+0000] {taskinstance.py:2306} INFO - Starting attempt 1 of 2
[2024-07-30T20:44:16.771+0000] {taskinstance.py:2330} INFO - Executing <Task(PythonOperator): transforms_data> on 2024-07-30 20:43:00+00:00
[2024-07-30T20:44:16.780+0000] {standard_task_runner.py:64} INFO - Started process 6957 to run task
[2024-07-30T20:44:16.783+0000] {standard_task_runner.py:90} INFO - Running: ['***', 'tasks', 'run', 'Pipeline', 'transforms_data', 'scheduled__2024-07-30T20:43:00+00:00', '--job-id', '507', '--raw', '--subdir', 'DAGS_FOLDER/pipeline.py', '--cfg-path', '/tmp/tmp4nt0rhmd']
[2024-07-30T20:44:16.786+0000] {standard_task_runner.py:91} INFO - Job 507: Subtask transforms_data
[2024-07-30T20:44:16.852+0000] {task_command.py:426} INFO - Running <TaskInstance: Pipeline.transforms_data scheduled__2024-07-30T20:43:00+00:00 [running]> on host f17ca52b44b4
[2024-07-30T20:44:16.960+0000] {taskinstance.py:2648} INFO - Exporting env vars: AIRFLOW_CTX_DAG_OWNER='***' AIRFLOW_CTX_DAG_ID='Pipeline' AIRFLOW_CTX_TASK_ID='transforms_data' AIRFLOW_CTX_EXECUTION_DATE='2024-07-30T20:43:00+00:00' AIRFLOW_CTX_TRY_NUMBER='1' AIRFLOW_CTX_DAG_RUN_ID='scheduled__2024-07-30T20:43:00+00:00'
[2024-07-30T20:44:16.962+0000] {taskinstance.py:430} INFO - ::endgroup::
[2024-07-30T20:44:16.979+0000] {taskinstance.py:441} INFO - ::group::Post task execution logs
[2024-07-30T20:44:16.981+0000] {taskinstance.py:2905} ERROR - Task failed with exception
Traceback (most recent call last):
  File "/home/airflow/.local/lib/python3.8/site-packages/airflow/models/taskinstance.py", line 465, in _execute_task
    result = _execute_callable(context=context, **execute_callable_kwargs)
  File "/home/airflow/.local/lib/python3.8/site-packages/airflow/models/taskinstance.py", line 432, in _execute_callable
    return execute_callable(context=context, **execute_callable_kwargs)
  File "/home/airflow/.local/lib/python3.8/site-packages/airflow/models/baseoperator.py", line 401, in wrapper
    return func(self, *args, **kwargs)
  File "/home/airflow/.local/lib/python3.8/site-packages/airflow/operators/python.py", line 235, in execute
    return_value = self.execute_callable()
  File "/home/airflow/.local/lib/python3.8/site-packages/airflow/operators/python.py", line 252, in execute_callable
    return self.python_callable(*self.op_args, **self.op_kwargs)
  File "/opt/airflow/dags/funtions.py", line 47, in transform_data
    raise FileNotFoundError("The Parquet file does not exist. Please check the previous task.")
FileNotFoundError: The Parquet file does not exist. Please check the previous task.
[2024-07-30T20:44:16.992+0000] {taskinstance.py:1206} INFO - Marking task as UP_FOR_RETRY. dag_id=Pipeline, task_id=transforms_data, run_id=scheduled__2024-07-30T20:43:00+00:00, execution_date=20240730T204300, start_date=20240730T204416, end_date=20240730T204416
[2024-07-30T20:44:17.002+0000] {standard_task_runner.py:110} ERROR - Failed to execute job 507 for task transforms_data (The Parquet file does not exist. Please check the previous task.; 6957)
[2024-07-30T20:44:17.037+0000] {local_task_job_runner.py:243} INFO - Task exited with return code 1
[2024-07-30T20:44:17.062+0000] {taskinstance.py:3503} INFO - 0 downstream tasks scheduled from follow-on schedule check
[2024-07-30T20:44:17.065+0000] {local_task_job_runner.py:222} INFO - ::endgroup::
